Workbook

Sheet README
A1: Edge agent literature review: data workbook
A3: Purpose | B3: Numbers, limitations, approaches and recommendations from the gap analysis, in sortable tables. Use the filter arrows on each header to sort or filter.
A4: Sheets | B4: Papers (key) | Metrics (every number, with location) | Comparisons (before/after, computed from Metrics) | Limitations (with an editable 'addressed by pipeline?' column) | Approaches | Frameworks | Recommendations
A5: How to update | B5: Edit values on Metrics. Comparisons look values up by ID, so they recalculate. To add a comparison, enter two Metrics IDs. Add rows directly under a table; it extends automatically.
A6: Colour legend | B6: Blue text = typed inputs. Black = formulas. Green = values pulled from another sheet. Yellow fill = my assumptions for you to review or overwrite.
A8: Assumptions I made
B9: Pipeline = the abstract you gave; no further detail was available.
B10: 'Relevance to pipeline' (Papers), 'Addressed by pipeline?' (Limitations) and 'Pipeline stage' (Approaches) are my judgments, shown in yellow.
B11: Percent values are stored as plain numbers (83.52 means 83.52%); the unit column says which. Ranges use 'Value' and 'Value (high end)'.
B12: Ahmed et al. numbers are simulated; the 'baseline' vs 'proposed' assignment follows the abstract's wording.
B13: Five papers (Shukla, Saad-Falcon, Ahmed, Ameur, Pavan) were read for abstract, results, limitations and future-work sections, not every page.
B14: 'Not assessed' in Limitations means I did not judge it against the pipeline.
A16: Live summary
A17: Rows in Papers (12 papers + 1 link list) | B17: =COUNTA(Papers!A:A)-1 -> 13
A18: Metrics recorded | B18: =COUNTA(Metrics!A:A)-1 -> 109
A19: Comparisons improved (of total) | B19: =COUNTIF(Comparisons!L:L,"Yes")&" of "&(COUNTA(Comparisons!A:A)-1) -> 14 of 22
A20: Limitations recorded | B20: =COUNTA(Limitations!A:A)-1 -> 41
A21: Addressed: Yes | B21: =COUNTIF(Limitations!F:F,"Yes") -> 0
A22: Addressed: Partial | B22: =COUNTIF(Limitations!F:F,"Partial") -> 9
A23: Addressed: No | B23: =COUNTIF(Limitations!F:F,"No") -> 20
A24: Addressed: Not assessed | B24: =COUNTIF(Limitations!F:F,"Not assessed") -> 12
A25: Metrics flagged for reliability | B25: =COUNTIF(Metrics!J:J,"?*") -> 23

Sheet Papers
A1: Short name | B1: Full title | C1: Year | D1: Venue / identifier | E1: Type | F1: Evidence level | G1: Tested on edge hardware? | H1: Relevance to pipeline (assumed) | I1: Notes
A2: Tian | B2: Beyond Scaling: Agents Are Heading to the Edge | C2: 2026 | D2: arXiv:2605.18535 | E2: Position paper | F2: No experiments (argument; cites others' results) | G2: No | H2: High | I2: Edge-native agents, SLM parity claim, deployment gap (Sec. 3.4), research agenda (Sec. 7).
A3: Shukla | B3: Adaptive Data Flywheel: Applying MAPE Control Loops to AI Agent Improvement | C3: 2025 | D3: arXiv:2510.27051 | E3: Case study | F3: Measured, production enterprise agent | G3: No (cloud enterprise) | H3: Medium | I3: Feedback-driven fine-tuning loop; 70B router replaced by fine-tuned 8B.
A4: Saad-Falcon | B4: Intelligence per Watt: Measuring Intelligence Efficiency of Local AI | C4: 2025 | D4: arXiv:2511.07885 (v5, 2026) | E4: Empirical study | F4: Measured + simulated routing | G4: Laptop/workstation accelerators (e.g. Apple M4 Max) | H4: High | I4: IPW metric; local vs cloud coverage; hybrid routing savings.
A5: Ahmed | B5: Privacy-Preserving Agentic AI at the Edge: Federated and Autonomous Intelligence for Smart Systems | C5: 2026 | D5: Spectrum of Engineering Sciences, vol. 4, p. 632 | E5: Conceptual framework | F5: Simulated only (Sec. 5.4) | G5: No | H5: Medium | I5: Reported metrics are simulated; baseline identity inferred from abstract wording.
A6: Ameur | B6: LLM-Powered Agentic AI for 5G/6G Networks: A Tutorial and Survey on Architectures, Protocols, and Standardization | C6: 2026 | D6: arXiv:2607.16066 | E6: Survey / tutorial | F6: Survey | G6: n/a | H6: Medium | I6: Open challenges in Sec. 6, incl. compression accuracy loss (Sec. 6.2).
A7: Pavan | B7: What Changes After Deployment? A Survey on On-device Learning in TinyML | C7: 2026 | D7: ACM Computing Surveys (arXiv:2605.31226) | E7: Survey | F7: Survey (~70 works) | G7: n/a | H7: High | I7: Distribution-change regimes; benchmark proposals (Sec. 7).
A8: Al-Atat | B8: The Case for Hierarchical Deep Learning Inference at the Network Edge | C8: 2023 | D8: arXiv:2304.11763 | E8: Empirical study | F8: Measured | G8: Yes (Raspberry Pi 4B + edge server) | H8: High | I8: Confidence-threshold offloading (Hierarchical Inference); classification tasks only.
A9: Andong | B9: Federated Multi-Agent Reinforcement Learning for Privacy-Preserving and Energy-Aware Resource Management in 6G Edge Networks (FERMI-6G) | C9: 2025 | D9: arXiv:2509.10163 | E9: Method paper | F9: Simulation (5 agents) | G9: No | H9: Low | I9: Network resource management, not LLM agents.
A10: Lovén | B10: Agentic Edge Intelligence: A Research Agenda | C10: 2025 | D10: Proc. UCC '25, Nantes, pp. 1-5 | E10: Position paper | F10: No experiments | G10: No | H10: Low | I10: Market-based negotiation of compute between agents.
A11: Agrawal | B11: LLM-Based Agents on the Edge: A Survey of Privacy, Scalability, Heterogeneity, and Autonomy | C11: 2026 | D11: IJCAI-26 Survey Track | E11: Survey | F11: Survey | G11: n/a | H11: High | I11: Taxonomy (Sec. 3); framework comparison (Table 1).
A12: Kadekodi | B12: AgentFlux: Decoupled Fine-Tuning & Inference for On-Device Agentic Systems | C12: 2025 | D12: arXiv:2510.00229 | E12: Method paper | F12: Measured (GPT-5 as judge) | G12: No (consumer GPUs, models <24 GB) | H12: High | I12: Separate LoRA adapters for tool selection and argument generation.
A13: Chen | B13: Octo-planner: On-device Language Model for Planner-Action Agents | C13: 2024 | D13: arXiv:2406.18082 | E13: Method paper | F13: Measured (GPT-4 as judge); no on-device latency/energy | G13: Not reported | H13: High | I13: Fine-tuned Phi-3 Mini planner; multi-LoRA merging.
A14: Link list | B14: Edge Agentic Systems: Retraining Approaches (reference links, compiled 2026-10-03) | C14: 2026 | D14: edge_agentic_retraining_links.pdf | E14: Reference list | F14: Not evidence | G14: n/a | H14: Low | I14: Document's own note: arXiv items are directional; blog/tutorial links are for orientation only.

Sheet Metrics
A1: ID | B1: Paper | C1: Metric | D1: Value | E1: Value (high end, if range) | F1: Unit | G1: Context / condition | H1: Location in paper | I1: Evidence type | J1: Reliability flag
A2: TIAN-01 | B2: Tian | C2: Parameter ratio, WideSeek-R1-4B vs DeepSeek-R1 (671B) | D2: 170 | F2: x | G2: Reported as comparable on structured tool-use / information-seeking benchmarks; result cited from another paper | H2: Sec. 3.3 | I2: Position paper (cited) | J2: Secondhand claim
A3: TIAN-02 | B3: Tian | C3: Local inference speed on consumer silicon | D3: 30 | E3: 80 | F3: tokens/s | G3: Apple M4 Pro, Snapdragon 8 Elite | H3: Sec. 3.3 | I3: Position paper (cited)
A4: TIAN-03 | B4: Tian | C4: Network overhead per step in cloud agents | D4: 200 | E4: 500 | F4: ms | G4: Compounds over a long action sequence | H4: Sec. 3.2, item 3 | I4: Position paper (cited)
A5: TIAN-04 | B5: Tian | C5: Sequential actions per autonomous task | D5: 50 | E5: 100 | F5: actions | H5: Sec. 3.2, item 3 | I5: Position paper (cited)
A6: TIAN-05 | B6: Tian | C6: Local voice-to-action latency (upper bound, 'below three seconds') | D6: 3 | F6: s | H6: Sec. 3.2, item 3 | I6: Position paper (cited) | J6: Upper bound, not a measurement
A7: SHUK-01 | B7: Shukla | C7: Negative feedback samples collected | D7: 495 | F7: count | G7: 3-month post-deployment window | H7: Abstract | I7: Measured (production)
A8: SHUK-02 | B8: Shukla | C8: User base | D8: 30000 | F8: users | G8: NVInfo AI employees | H8: Abstract | I8: Measured (production)
A9: SHUK-03 | B9: Shukla | C9: Feedback participation rate | D9: =D7/D8*100 -> 1.65 | F9: % | G9: Derived: samples / users | H9: Discussion, subsection B | I9: Derived | J9: Formula
A10: SHUK-04 | B10: Shukla | C10: Routing error share of failures | D10: 5.25 | F10: % | H10: Abstract | I10: Measured (production)
A11: SHUK-05 | B11: Shukla | C11: Query rephrasal error share of failures | D11: 3.2 | F11: % | H11: Abstract | I11: Measured (production)
A12: SHUK-06 | B12: Shukla | C12: Router model size before | D12: 70 | F12: B params | G12: Llama 3.1 70B | H12: Abstract | I12: Measured (production)
A13: SHUK-07 | B13: Shukla | C13: Router model size after (fine-tuned) | D13: 8 | F13: B params | G13: Fine-tuned 8B variant | H13: Abstract | I13: Measured (production)
A14: SHUK-08 | B14: Shukla | C14: Router accuracy after fine-tuning | D14: 96 | F14: % | H14: Abstract | I14: Measured (production)
A15: SHUK-09 | B15: Shukla | C15: Router latency reduction | D15: 70 | F15: % | H15: Abstract | I15: Measured (production)
A16: SHUK-10 | B16: Shukla | C16: Query rephrasal accuracy gain | D16: 3.7 | F16: % (as reported) | G16: Synthetic dataset of 5,000 examples, 80/10/10 split | H16: Abstract; Introduction | I16: Measured (production) | J16: Unclear whether percentage points or relative
A17: SHUK-11 | B17: Shukla | C17: Query rephrasal latency reduction | D17: 40 | F17: % | H17: Abstract | I17: Measured (production)
A18: SHUK-12 | B18: Shukla | C18: Synthetic training examples for rephrasal | D18: 5000 | F18: count | H18: Introduction | I18: Measured (production)
A19: IPW-01 | B19: Saad-Falcon | C19: Single-turn queries answerable locally (best-of-local ensemble) | D19: 88.7 | F19: % | G19: 20+ local models, 1M queries | H19: Abstract | I19: Measured | J19: Single-turn chat/reasoning only
A20: IPW-02 | B20: Saad-Falcon | C20: Locally-serviceable query coverage, 2023 | D20: 23.2 | F20: % | G20: Win/tie rate vs frontier models | H20: Abstract | I20: Measured
A21: IPW-03 | B21: Saad-Falcon | C21: Locally-serviceable query coverage, 2025 | D21: 71.3 | F21: % | G21: Win/tie rate vs frontier models | H21: Abstract | I21: Measured
A22: IPW-04 | B22: Saad-Falcon | C22: IPW improvement 2023-2025 | D22: 5.3 | F22: x | H22: Abstract; Sec. 5 | I22: Measured
A23: IPW-05 | B23: Saad-Falcon | C23: IPW gain from models | D23: 3.1 | F23: x | H23: Sec. 5 (Conclusion) | I23: Measured
A24: IPW-06 | B24: Saad-Falcon | C24: IPW gain from hardware | D24: 1.7 | F24: x | H24: Sec. 5 (Conclusion) | I24: Measured
A25: IPW-07 | B25: Saad-Falcon | C25: Cloud accelerator per-query efficiency edge over local | D25: 1.4 | E25: 7.4 | F25: x | G25: Identical models; batch size 1 | H25: Sec. 5 (Conclusion); App. E.8 | I25: Measured
A26: IPW-08 | B26: Saad-Falcon | C26: Hybrid local-cloud routing reduction (energy, compute, cost) | D26: 60 | E26: 80 | F26: % | G26: Versus batched cloud baseline | H26: Abstract; Sec. 4.3 | I26: Simulated routing
A27: IPW-09 | B27: Saad-Falcon | C27: Oracle routing energy reduction | D27: 80.4 | F27: % | G27: 24 h, 80.2M queries | H27: Sec. 4.3 | I27: Simulated routing
A28: IPW-10 | B28: Saad-Falcon | C28: Oracle routing compute reduction | D28: 77.3 | F28: % | H28: Sec. 4.3 | I28: Simulated routing
A29: IPW-11 | B29: Saad-Falcon | C29: Oracle routing cost reduction | D29: 73.8 | F29: % | H29: Sec. 4.3 | I29: Simulated routing
A30: IPW-12 | B30: Saad-Falcon | C30: 80%-accurate router energy reduction | D30: 64.3 | F30: % | G30: Misrouted queries fall back to the cloud model | H30: Sec. 4.3 | I30: Simulated routing
A31: IPW-13 | B31: Saad-Falcon | C31: 80%-accurate router compute reduction | D31: 61.8 | F31: % | H31: Sec. 4.3 | I31: Simulated routing
A32: IPW-14 | B32: Saad-Falcon | C32: 80%-accurate router cost reduction | D32: 59 | F32: % | H32: Sec. 4.3 | I32: Simulated routing
A33: IPW-15 | B33: Saad-Falcon | C33: Power telemetry error | D33: 10 | E33: 15 | F33: % | G33: Software telemetry (NVML, powermetrics, ROCm SMI) | H33: App. C, item 1 | I33: Stated limitation
A34: AHM-01 | B34: Ahmed | C34: Raw data exposure (proposed framework) | D34: 0 | F34: % | H34: Abstract | I34: Simulated | J34: Simulated, not measured on hardware; baseline identity inferred from abstract wording
A35: AHM-02 | B35: Ahmed | C35: Communication cost, baseline | D35: 480 | F35: MB/round | H35: Abstract | I35: Simulated | J35: Simulated, not measured on hardware; baseline identity inferred from abstract wording
A36: AHM-03 | B36: Ahmed | C36: Communication cost, proposed | D36: 38 | F36: MB/round | H36: Abstract | I36: Simulated | J36: Simulated, not measured on hardware; baseline identity inferred from abstract wording
A37: AHM-04 | B37: Ahmed | C37: Latency, baseline | D37: 142 | F37: ms | H37: Abstract | I37: Simulated | J37: Simulated, not measured on hardware; baseline identity inferred from abstract wording
A38: AHM-05 | B38: Ahmed | C38: Latency, proposed | D38: 67 | F38: ms | H38: Abstract | I38: Simulated | J38: Simulated, not measured on hardware; baseline identity inferred from abstract wording
A39: AHM-06 | B39: Ahmed | C39: Model accuracy, baseline | D39: 93.8 | F39: % | H39: Abstract | I39: Simulated | J39: Simulated, not measured on hardware; baseline identity inferred from abstract wording
A40: AHM-07 | B40: Ahmed | C40: Model accuracy, proposed | D40: 92.6 | F40: % | H40: Abstract | I40: Simulated | J40: Simulated, not measured on hardware; baseline identity inferred from abstract wording
...

Sheet Comparisons
A1: ID | B1: Comparison | C1: Paper | D1: Before ID | E1: Before value | F1: After ID | G1: After value | H1: Unit | I1: Change (in unit) | J1: Relative change | K1: Better direction | L1: Improved? | M1: Notes
A2: CMP-01 | B2: HI accuracy vs full offload (CIFAR-10) | C2: Al-Atat | D2: HI-03 | E2: =IFERROR(INDEX(Metrics!$D:$D,MATCH($D2,Metrics!$A:$A,0)),"ID not found") -> 95 | F2: HI-06 | G2: =IFERROR(INDEX(Metrics!$D:$D,MATCH($F2,Metrics!$A:$A,0)),"ID not found") -> 83.52 | H2: =IFERROR(INDEX(Metrics!$F:$F,MATCH($D2,Metrics!$A:$A,0)),"ID not found") -> % | I2: =IFERROR(G2-E2,"") -> -11.48 | J2: =IFERROR(IF(E2=0,"",(G2-E2)/E2),"") -> -0.12084211 | K2: Higher | L2: =IFERROR(IF(K2="Higher",IF(G2>E2,"Yes","No"),IF(G2<E2,"Yes","No")),"") -> No | M2: Accuracy given up by offloading only low-confidence samples
A3: CMP-02 | B3: HI accuracy vs no offload (CIFAR-10) | C3: Al-Atat | D3: HI-01 | E3: =IFERROR(INDEX(Metrics!$D:$D,MATCH($D3,Metrics!$A:$A,0)),"ID not found") -> 62.58 | F3: HI-06 | G3: =IFERROR(INDEX(Metrics!$D:$D,MATCH($F3,Metrics!$A:$A,0)),"ID not found") -> 83.52 | H3: =IFERROR(INDEX(Metrics!$F:$F,MATCH($D3,Metrics!$A:$A,0)),"ID not found") -> % | I3: =IFERROR(G3-E3,"") -> 20.94 | J3: =IFERROR(IF(E3=0,"",(G3-E3)/E3),"") -> 0.3346117 | K3: Higher | L3: =IFERROR(IF(K3="Higher",IF(G3>E3,"Yes","No"),IF(G3<E3,"Yes","No")),"") -> Yes
A4: CMP-03 | B4: HI offloaded share vs full offload | C4: Al-Atat | D4: HI-07 | E4: =IFERROR(INDEX(Metrics!$D:$D,MATCH($D4,Metrics!$A:$A,0)),"ID not found") -> 100 | F4: HI-05 | G4: =IFERROR(INDEX(Metrics!$D:$D,MATCH($F4,Metrics!$A:$A,0)),"ID not found") -> 35.5 | H4: =IFERROR(INDEX(Metrics!$F:$F,MATCH($D4,Metrics!$A:$A,0)),"ID not found") -> % | I4: =IFERROR(G4-E4,"") -> -64.5 | J4: =IFERROR(IF(E4=0,"",(G4-E4)/E4),"") -> -0.645 | K4: Lower | L4: =IFERROR(IF(K4="Higher",IF(G4>E4,"Yes","No"),IF(G4<E4,"Yes","No")),"") -> Yes
A5: CMP-04 | B5: Time: offload + server vs on-device inference | C5: Al-Atat | D5: HI-20 | E5: =IFERROR(INDEX(Metrics!$D:$D,MATCH($D5,Metrics!$A:$A,0)),"ID not found") -> 74.34 | F5: HI-19 | G5: =IFERROR(INDEX(Metrics!$D:$D,MATCH($F5,Metrics!$A:$A,0)),"ID not found") -> 0.99 | H5: =IFERROR(INDEX(Metrics!$F:$F,MATCH($D5,Metrics!$A:$A,0)),"ID not found") -> ms | I5: =IFERROR(G5-E5,"") -> -73.35 | J5: =IFERROR(IF(E5=0,"",(G5-E5)/E5),"") -> -0.98668281 | K5: Lower | L5: =IFERROR(IF(K5="Higher",IF(G5>E5,"Yes","No"),IF(G5<E5,"Yes","No")),"") -> Yes | M5: On-device is the 'After'
A6: CMP-05 | B6: Router size: 70B to fine-tuned 8B | C6: Shukla | D6: SHUK-06 | E6: =IFERROR(INDEX(Metrics!$D:$D,MATCH($D6,Metrics!$A:$A,0)),"ID not found") -> 70 | F6: SHUK-07 | G6: =IFERROR(INDEX(Metrics!$D:$D,MATCH($F6,Metrics!$A:$A,0)),"ID not found") -> 8 | H6: =IFERROR(INDEX(Metrics!$F:$F,MATCH($D6,Metrics!$A:$A,0)),"ID not found") -> B params | I6: =IFERROR(G6-E6,"") -> -62 | J6: =IFERROR(IF(E6=0,"",(G6-E6)/E6),"") -> -0.88571429 | K6: Lower | L6: =IFERROR(IF(K6="Higher",IF(G6>E6,"Yes","No"),IF(G6<E6,"Yes","No")),"") -> Yes
A7: CMP-06 | B7: Local-serviceable coverage 2023 to 2025 | C7: Saad-Falcon | D7: IPW-02 | E7: =IFERROR(INDEX(Metrics!$D:$D,MATCH($D7,Metrics!$A:$A,0)),"ID not found") -> 23.2 | F7: IPW-03 | G7: =IFERROR(INDEX(Metrics!$D:$D,MATCH($F7,Metrics!$A:$A,0)),"ID not found") -> 71.3 | H7: =IFERROR(INDEX(Metrics!$F:$F,MATCH($D7,Metrics!$A:$A,0)),"ID not found") -> % | I7: =IFERROR(G7-E7,"") -> 48.1 | J7: =IFERROR(IF(E7=0,"",(G7-E7)/E7),"") -> 2.0732759 | K7: Higher | L7: =IFERROR(IF(K7="Higher",IF(G7>E7,"Yes","No"),IF(G7<E7,"Yes","No")),"") -> Yes
A8: CMP-07 | B8: Energy saving: oracle router vs 80%-accurate router | C8: Saad-Falcon | D8: IPW-09 | E8: =IFERROR(INDEX(Metrics!$D:$D,MATCH($D8,Metrics!$A:$A,0)),"ID not found") -> 80.4 | F8: IPW-12 | G8: =IFERROR(INDEX(Metrics!$D:$D,MATCH($F8,Metrics!$A:$A,0)),"ID not found") -> 64.3 | H8: =IFERROR(INDEX(Metrics!$F:$F,MATCH($D8,Metrics!$A:$A,0)),"ID not found") -> % | I8: =IFERROR(G8-E8,"") -> -16.1 | J8: =IFERROR(IF(E8=0,"",(G8-E8)/E8),"") -> -0.20024876 | K8: Higher | L8: =IFERROR(IF(K8="Higher",IF(G8>E8,"Yes","No"),IF(G8<E8,"Yes","No")),"") -> No | M8: 'After' is the realistic router; shows share of oracle gain kept
A9: CMP-08 | B9: Communication cost: baseline vs proposed | C9: Ahmed | D9: AHM-02 | E9: =IFERROR(INDEX(Metrics!$D:$D,MATCH($D9,Metrics!$A:$A,0)),"ID not found") -> 480 | F9: AHM-03 | G9: =IFERROR(INDEX(Metrics!$D:$D,MATCH($F9,Metrics!$A:$A,0)),"ID not found") -> 38 | H9: =IFERROR(INDEX(Metrics!$F:$F,MATCH($D9,Metrics!$A:$A,0)),"ID not found") -> MB/round | I9: =IFERROR(G9-E9,"") -> -442 | J9: =IFERROR(IF(E9=0,"",(G9-E9)/E9),"") -> -0.92083333 | K9: Lower | L9: =IFERROR(IF(K9="Higher",IF(G9>E9,"Yes","No"),IF(G9<E9,"Yes","No")),"") -> Yes | M9: Simulated
A10: CMP-09 | B10: Latency: baseline vs proposed | C10: Ahmed | D10: AHM-04 | E10: =IFERROR(INDEX(Metrics!$D:$D,MATCH($D10,Metrics!$A:$A,0)),"ID not found") -> 142 | F10: AHM-05 | G10: =IFERROR(INDEX(Metrics!$D:$D,MATCH($F10,Metrics!$A:$A,0)),"ID not found") -> 67 | H10: =IFERROR(INDEX(Metrics!$F:$F,MATCH($D10,Metrics!$A:$A,0)),"ID not found") -> ms | I10: =IFERROR(G10-E10,"") -> -75 | J10: =IFERROR(IF(E10=0,"",(G10-E10)/E10),"") -> -0.52816901 | K10: Lower | L10: =IFERROR(IF(K10="Higher",IF(G10>E10,"Yes","No"),IF(G10<E10,"Yes","No")),"") -> Yes | M10: Simulated
A11: CMP-10 | B11: Accuracy: baseline vs proposed | C11: Ahmed | D11: AHM-06 | E11: =IFERROR(INDEX(Metrics!$D:$D,MATCH($D11,Metrics!$A:$A,0)),"ID not found") -> 93.8 | F11: AHM-07 | G11: =IFERROR(INDEX(Metrics!$D:$D,MATCH($F11,Metrics!$A:$A,0)),"ID not found") -> 92.6 | H11: =IFERROR(INDEX(Metrics!$F:$F,MATCH($D11,Metrics!$A:$A,0)),"ID not found") -> % | I11: =IFERROR(G11-E11,"") -> -1.2 | J11: =IFERROR(IF(E11=0,"",(G11-E11)/E11),"") -> -0.012793177 | K11: Higher | L11: =IFERROR(IF(K11="Higher",IF(G11>E11,"Yes","No"),IF(G11<E11,"Yes","No")),"") -> No | M11: Simulated; accuracy cost of privacy framework
A12: CMP-11 | B12: Energy per task: centralized RL vs FERMI-6G | C12: Andong | D12: FER-04 | E12: =IFERROR(INDEX(Metrics!$D:$D,MATCH($D12,Metrics!$A:$A,0)),"ID not found") -> 0.0663 | F12: FER-05 | G12: =IFERROR(INDEX(Metrics!$D:$D,MATCH($F12,Metrics!$A:$A,0)),"ID not found") -> 0.023 | H12: =IFERROR(INDEX(Metrics!$F:$F,MATCH($D12,Metrics!$A:$A,0)),"ID not found") -> J/task | I12: =IFERROR(G12-E12,"") -> -0.0433 | J12: =IFERROR(IF(E12=0,"",(G12-E12)/E12),"") -> -0.65309201 | K12: Lower | L12: =IFERROR(IF(K12="Higher",IF(G12>E12,"Yes","No"),IF(G12<E12,"Yes","No")),"") -> Yes | M12: Baseline environment was simplified
A13: CMP-12 | B13: FERMI-6G fairness: Table II vs Discussion text | C13: Andong | D13: FER-06 | E13: =IFERROR(INDEX(Metrics!$D:$D,MATCH($D13,Metrics!$A:$A,0)),"ID not found") -> 0.79 | F13: FER-07 | G13: =IFERROR(INDEX(Metrics!$D:$D,MATCH($F13,Metrics!$A:$A,0)),"ID not found") -> 0.3734 | H13: =IFERROR(INDEX(Metrics!$F:$F,MATCH($D13,Metrics!$A:$A,0)),"ID not found") -> index | I13: =IFERROR(G13-E13,"") -> -0.4166 | J13: =IFERROR(IF(E13=0,"",(G13-E13)/E13),"") -> -0.52734177 | K13: Higher | L13: =IFERROR(IF(K13="Higher",IF(G13>E13,"Yes","No"),IF(G13<E13,"Yes","No")),"") -> No | M13: Same paper, two different values
A14: CMP-13 | B14: Reliability with 50 agents: centralized RL vs FERMI-6G | C14: Andong | D14: FER-09 | E14: =IFERROR(INDEX(Metrics!$D:$D,MATCH($D14,Metrics!$A:$A,0)),"ID not found") -> 12.38 | F14: FER-10 | G14: =IFERROR(INDEX(Metrics!$D:$D,MATCH($F14,Metrics!$A:$A,0)),"ID not found") -> 90.01 | H14: =IFERROR(INDEX(Metrics!$F:$F,MATCH($D14,Metrics!$A:$A,0)),"ID not found") -> % | I14: =IFERROR(G14-E14,"") -> 77.63 | J14: =IFERROR(IF(E14=0,"",(G14-E14)/E14),"") -> 6.2705977 | K14: Higher | L14: =IFERROR(IF(K14="Higher",IF(G14>E14,"Yes","No"),IF(G14<E14,"Yes","No")),"") -> Yes
A15: CMP-14 | B15: ToolFit: base to hierarchical orchestration | C15: Kadekodi | D15: AFX-01 | E15: =IFERROR(INDEX(Metrics!$D:$D,MATCH($D15,Metrics!$A:$A,0)),"ID not found") -> 10.4 | F15: AFX-02 | G15: =IFERROR(INDEX(Metrics!$D:$D,MATCH($F15,Metrics!$A:$A,0)),"ID not found") -> 16 | H15: =IFERROR(INDEX(Metrics!$F:$F,MATCH($D15,Metrics!$A:$A,0)),"ID not found") -> % | I15: =IFERROR(G15-E15,"") -> 5.6 | J15: =IFERROR(IF(E15=0,"",(G15-E15)/E15),"") -> 0.53846154 | K15: Higher | L15: =IFERROR(IF(K15="Higher",IF(G15>E15,"Yes","No"),IF(G15<E15,"Yes","No")),"") -> Yes
A16: CMP-15 | B16: ToolFit: hierarchical to + traditional fine-tuning | C16: Kadekodi | D16: AFX-02 | E16: =IFERROR(INDEX(Metrics!$D:$D,MATCH($D16,Metrics!$A:$A,0)),"ID not found") -> 16 | F16: AFX-03 | G16: =IFERROR(INDEX(Metrics!$D:$D,MATCH($F16,Metrics!$A:$A,0)),"ID not found") -> 39 | H16: =IFERROR(INDEX(Metrics!$F:$F,MATCH($D16,Metrics!$A:$A,0)),"ID not found") -> % | I16: =IFERROR(G16-E16,"") -> 23 | J16: =IFERROR(IF(E16=0,"",(G16-E16)/E16),"") -> 1.4375 | K16: Higher | L16: =IFERROR(IF(K16="Higher",IF(G16>E16,"Yes","No"),IF(G16<E16,"Yes","No")),"") -> Yes
A17: CMP-16 | B17: ToolFit: hierarchical to + decoupled fine-tuning | C17: Kadekodi | D17: AFX-02 | E17: =IFERROR(INDEX(Metrics!$D:$D,MATCH($D17,Metrics!$A:$A,0)),"ID not found") -> 16 | F17: AFX-04 | G17: =IFERROR(INDEX(Metrics!$D:$D,MATCH($F17,Metrics!$A:$A,0)),"ID not found") -> 61.5 | H17: =IFERROR(INDEX(Metrics!$F:$F,MATCH($D17,Metrics!$A:$A,0)),"ID not found") -> % | I17: =IFERROR(G17-E17,"") -> 45.5 | J17: =IFERROR(IF(E17=0,"",(G17-E17)/E17),"") -> 2.84375 | K17: Higher | L17: =IFERROR(IF(K17="Higher",IF(G17>E17,"Yes","No"),IF(G17<E17,"Yes","No")),"") -> Yes
A18: CMP-17 | B18: ToolFit: local tool selection to GPT-5-mini tool selection | C18: Kadekodi | D18: AFX-05 | E18: =IFERROR(INDEX(Metrics!$D:$D,MATCH($D18,Metrics!$A:$A,0)),"ID not found") -> 16 | F18: AFX-06 | G18: =IFERROR(INDEX(Metrics!$D:$D,MATCH($F18,Metrics!$A:$A,0)),"ID not found") -> 60.8 | H18: =IFERROR(INDEX(Metrics!$F:$F,MATCH($D18,Metrics!$A:$A,0)),"ID not found") -> % | I18: =IFERROR(G18-E18,"") -> 44.8 | J18: =IFERROR(IF(E18=0,"",(G18-E18)/E18),"") -> 2.8 | K18: Higher | L18: =IFERROR(IF(K18="Higher",IF(G18>E18,"Yes","No"),IF(G18<E18,"Yes","No")),"") -> Yes | M18: Tool selection is the main bottleneck
A19: CMP-18 | B19: ToolFit: local arguments to GPT-5-mini arguments | C19: Kadekodi | D19: AFX-05 | E19: =IFERROR(INDEX(Metrics!$D:$D,MATCH($D19,Metrics!$A:$A,0)),"ID not found") -> 16 | F19: AFX-07 | G19: =IFERROR(INDEX(Metrics!$D:$D,MATCH($F19,Metrics!$A:$A,0)),"ID not found") -> 28.8 | H19: =IFERROR(INDEX(Metrics!$F:$F,MATCH($D19,Metrics!$A:$A,0)),"ID not found") -> % | I19: =IFERROR(G19-E19,"") -> 12.8 | J19: =IFERROR(IF(E19=0,"",(G19-E19)/E19),"") -> 0.8 | K19: Higher | L19: =IFERROR(IF(K19="Higher",IF(G19>E19,"Yes","No"),IF(G19<E19,"Yes","No")),"") -> Yes
A20: CMP-19 | B20: Planner accuracy: full fine-tuning vs LoRA rank 64 | C20: Chen | D20: OCT-01 | E20: =IFERROR(INDEX(Metrics!$D:$D,MATCH($D20,Metrics!$A:$A,0)),"ID not found") -> 98.1 | F20: OCT-02 | G20: =IFERROR(INDEX(Metrics!$D:$D,MATCH($F20,Metrics!$A:$A,0)),"ID not found") -> 85.1 | H20: =IFERROR(INDEX(Metrics!$F:$F,MATCH($D20,Metrics!$A:$A,0)),"ID not found") -> % | I20: =IFERROR(G20-E20,"") -> -13 | J20: =IFERROR(IF(E20=0,"",(G20-E20)/E20),"") -> -0.13251784 | K20: Higher | L20: =IFERROR(IF(K20="Higher",IF(G20>E20,"Yes","No"),IF(G20<E20,"Yes","No")),"") -> No
A21: CMP-20 | B21: Planner accuracy: LoRA rank 64 vs rank 16 | C21: Chen | D21: OCT-02 | E21: =IFERROR(INDEX(Metrics!$D:$D,MATCH($D21,Metrics!$A:$A,0)),"ID not found") -> 85.1 | F21: OCT-03 | G21: =IFERROR(INDEX(Metrics!$D:$D,MATCH($F21,Metrics!$A:$A,0)),"ID not found") -> 72.9 | H21: =IFERROR(INDEX(Metrics!$F:$F,MATCH($D21,Metrics!$A:$A,0)),"ID not found") -> % | I21: =IFERROR(G21-E21,"") -> -12.2 | J21: =IFERROR(IF(E21=0,"",(G21-E21)/E21),"") -> -0.14336075 | K21: Higher | L21: =IFERROR(IF(K21="Higher",IF(G21>E21,"Yes","No"),IF(G21<E21,"Yes","No")),"") -> No
A22: CMP-21 | B22: Multi-LoRA accuracy: 1 domain to 4 domains | C22: Chen | D22: OCT-04 | E22: =IFERROR(INDEX(Metrics!$D:$D,MATCH($D22,Metrics!$A:$A,0)),"ID not found") -> 85.1 | F22: OCT-07 | G22: =IFERROR(INDEX(Metrics!$D:$D,MATCH($F22,Metrics!$A:$A,0)),"ID not found") -> 69.7 | H22: =IFERROR(INDEX(Metrics!$F:$F,MATCH($D22,Metrics!$A:$A,0)),"ID not found") -> % | I22: =IFERROR(G22-E22,"") -> -15.4 | J22: =IFERROR(IF(E22=0,"",(G22-E22)/E22),"") -> -0.18096357 | K22: Higher | L22: =IFERROR(IF(K22="Higher",IF(G22>E22,"Yes","No"),IF(G22<E22,"Yes","No")),"") -> No
A23: CMP-22 | B23: Planner accuracy: 1000 vs 100 training examples | C23: Chen | D23: OCT-10 | E23: =IFERROR(INDEX(Metrics!$D:$D,MATCH($D23,Metrics!$A:$A,0)),"ID not found") -> 98.1 | F23: OCT-13 | G23: =IFERROR(INDEX(Metrics!$D:$D,MATCH($F23,Metrics!$A:$A,0)),"ID not found") -> 78.1 | H23: =IFERROR(INDEX(Metrics!$F:$F,MATCH($D23,Metrics!$A:$A,0)),"ID not found") -> % | I23: =IFERROR(G23-E23,"") -> -20 | J23: =IFERROR(IF(E23=0,"",(G23-E23)/E23),"") -> -0.2038736 | K23: Higher | L23: =IFERROR(IF(K23="Higher",IF(G23>E23,"Yes","No"),IF(G23<E23,"Yes","No")),"") -> No

Sheet Limitations
A1: ID | B1: Paper | C1: Limitation / gap | D1: Category | E1: Location in paper | F1: Addressed by pipeline? (assumed) | G1: Pipeline note
A2: LIM-01 | B2: Tian | C2: SLM parity evidence comes from standard benchmarks; long-tail production failures not captured | D2: Evaluation | E2: Sec. 6.2 | F2: Not assessed
A3: LIM-02 | B3: Tian | C3: Federated post-training on interaction traces is unsolved | D3: Post-deployment learning | E3: Sec. 6.2; Sec. 7 item 1 | F3: No | G3: Pipeline abstract has no federated or on-device learning step
A4: LIM-03 | B4: Tian | C4: Catastrophic forgetting during local adaptation | D4: Post-deployment learning | E4: Sec. 7 item 1 | F4: No
A5: LIM-04 | B5: Tian | C5: Small models cannot recover from errors by scale; need lightweight error correction | D5: Capability | E5: Sec. 3.4 item 4; Sec. 7 item 2 | F5: No
A6: LIM-05 | B6: Tian | C6: Accuracy-only leaderboards; need latency, energy, memory, offline-failure scoring | D6: Evaluation | E6: Sec. 7 item 6 | F6: No | G6: Addressed only if the pipeline adds these metrics
A7: LIM-06 | B7: Shukla | C7: Low feedback participation (495 of 30,000 users) | D7: Post-deployment learning | E7: Discussion, subsection B | F7: Not assessed
A8: LIM-07 | B8: Shukla | C8: Manual error analysis does not scale | D8: Post-deployment learning | E8: Discussion, subsection B | F8: Not assessed
A9: LIM-08 | B9: Shukla | C9: Privacy rules blocked storing query-response pairs | D9: Privacy | E9: Discussion, subsection B | F9: Partial | G9: Local learning keeps data on device, if the pipeline includes on-device adaptation (unspecified)
A10: LIM-09 | B10: Shukla | C10: Continual learning without forgetting | D10: Post-deployment learning | E10: Discussion, subsection D | F10: No
A11: LIM-10 | B11: Saad-Falcon | C11: Single-turn queries only; agentic routing must count cumulative trajectory cost | D11: Scope | E11: App. C item 2; App. D.1 | F11: Partial | G11: Pipeline targets agentic setting; trajectory cost not yet defined
A12: LIM-11 | B12: Saad-Falcon | C12: Software power telemetry has 10-15% error | D12: Evaluation | E12: App. C item 1 | F12: No | G12: Use a hardware power meter
A13: LIM-12 | B13: Saad-Falcon | C13: Judged by an LLM (Qwen3-235B) | D13: Evaluation | E13: App. C item 3 | F13: No
A14: LIM-13 | B14: Saad-Falcon | C14: Hardware coverage excludes other mobile NPUs and edge accelerators | D14: Hardware | E14: App. C item 4 | F14: No
A15: LIM-14 | B15: Ahmed | C15: Simulated only; assumes perfectly working policy and privacy engines | D15: Evaluation | E15: Sec. 5.4 | F15: Not assessed
A16: LIM-15 | B16: Ahmed | C16: Privacy defined on data and updates, not on agent behavior (memory, disclosures to other agents) | D16: Privacy | E16: Sec. 2.3 | F16: Partial | G16: Localization reduces exposure; agent-level behavior not covered
A17: LIM-16 | B17: Ameur | C17: Compression accuracy loss on domain reasoning is uncharacterized | D17: Compression | E17: Sec. 6.2 | F17: Partial | G17: Opportunity: measure it for agentic tasks
A18: LIM-17 | B18: Ameur | C18: LLM latency exceeds control-loop time scales | D18: Capability | E18: Sec. 6.3 | F18: Not assessed
A19: LIM-18 | B19: Ameur | C19: No domain-specific agentic benchmarks | D19: Evaluation | E19: Sec. 6.5 | F19: Not assessed
A20: LIM-19 | B20: Ameur | C20: Data-sovereignty rules block sending full state to third-party LLMs | D20: Privacy | E20: Sec. 6.6 | F20: Partial | G20: Localization addresses this directly
A21: LIM-20 | B21: Pavan | C21: No standard evaluation for on-device learning; benchmark vs real-deployment gap | D21: Evaluation | E21: Abstract; Sec. 7 | F21: No
A22: LIM-21 | B22: Pavan | C22: Solution components optimized in isolation; no end-to-end design tools | D22: Compression | E22: Sec. 7 (End-to-end design) | F22: Partial | G22: Pipeline combines techniques, but joint optimization not specified
A23: LIM-22 | B23: Pavan | C23: Peak RAM often omits the buffer memory | D23: Evaluation | E23: Metrics discussion before Sec. 7 | F23: No | G23: Report KV cache and adapter memory too
A24: LIM-23 | B24: Al-Atat | C24: Device cannot know whether its own answer is correct | D24: Fallback | E24: Sec. 1 (Challenges of HI) | F24: Partial | G24: Pipeline must define the fallback trigger
A25: LIM-24 | B25: Al-Atat | C25: Assumes the edge server is reachable | D25: Fallback | E25: Sec. 1; Sec. 6 | F25: Partial | G25: Pipeline targets no-connection failures
A26: LIM-25 | B26: Al-Atat | C26: Dog-breed result assumes a 100%-accurate large model | D26: Evaluation | E26: Sec. 5 (L-ML) | F26: Not assessed
A27: LIM-26 | B27: Al-Atat | C27: DNN partitioning infeasible on MCU/IoT-class devices | D27: Hardware | E27: Appendix; Table 6 | F27: Not assessed
A28: LIM-27 | B28: Al-Atat | C28: Classification tasks only, no agentic loop | D28: Scope | E28: Sec. 3-6 | F28: No
A29: LIM-28 | B29: Andong | C29: Baselines simplified; direct comparison may be misleading | D29: Evaluation | E29: Sec. VI | F29: Not assessed
A30: LIM-29 | B30: Andong | C30: Fairness, URLLC latency, real testbed validation open | D30: Evaluation | E30: Sec. VII | F30: Not assessed
A31: LIM-30 | B31: Lovén | C31: Assumes agents rent compute from nearby nodes, which conflicts with full localization | D31: Fallback | E31: Sec. 3 (examples) | F31: Not assessed | G31: Divergent from pipeline objective
A32: LIM-31 | B32: Agrawal | C32: No existing framework achieves privacy, scalability, heterogeneity and autonomy together | D32: Scope | E32: Sec. 5; Table 1 | F32: Not assessed
A33: LIM-32 | B33: Agrawal | C33: On-device agents need external support and connectivity for complex or high-risk tasks | D33: Fallback | E33: Sec. 4.4 (Deployment) | F33: Partial | G33: Directly targeted; evidence needed
A34: LIM-33 | B34: Agrawal | C34: Single small-model agents struggle with multi-step tool use and error recovery | D34: Capability | E34: Sec. 3 (single-agent pattern) | F34: No
A35: LIM-34 | B35: Agrawal | C35: Local fine-tuning can forget previously learned knowledge | D35: Post-deployment learning | E35: Sec. 3 (adaptation pattern) | F35: No
A36: LIM-35 | B36: Kadekodi | C36: Tool selection is the main failure of local models | D36: Capability | E36: Sec. 3.4; Table 2 | F36: No
A37: LIM-36 | B37: Kadekodi | C37: Long tool descriptions (30 tools = 9.8K tokens) lower accuracy | D37: Capability | E37: Sec. 3.5 | F37: No
A38: LIM-37 | B38: Kadekodi | C38: Each new tool requires fine-tuning new adapters | D38: Post-deployment learning | E38: Sec. 6 | F38: No
A39: LIM-38 | B39: Kadekodi | C39: Tested on consumer GPUs, not IoT-class devices | D39: Hardware | E39: Sec. 3.2 | F39: No
A40: LIM-39 | B40: Chen | C40: Plans are fixed in advance; not adaptive to feedback | D40: Capability | E40: Limitations and future work | F40: No
...

Sheet Approaches
A1: Category | B1: Approach | C1: Paper | D1: Location in paper | E1: Reported result | F1: Pipeline stage (assumed)
A2: Compression | B2: Weight quantization to 4-bit / FP4; FP4 on a larger model beats a smaller model at higher precision | C2: Saad-Falcon | D2: Sec. 5 (Conclusion); App. E.1 | E2: IPW best on memory-rich devices (MoE) | F2: Compression
A3: Compression | B3: 4-bit quantization, structured pruning, knowledge distillation | C3: Ameur | D3: Sec. 2 (AIOps paragraph); Sec. 6.2 | E3: 4-8x memory reduction; accuracy loss uncharacterized | F3: Compression
A4: Compression | B4: Replace a large router with a fine-tuned small model | C4: Shukla | D4: Abstract | E4: 70B to 8B, 96% accuracy, 70% lower latency | F4: Compression
A5: Compression | B5: Quantized TFLite small models | C5: Al-Atat | D5: Sec. 4-5 | E5: 0.45 MB / 0.23 MB, 62.58% / 63.86% accuracy | F5: Compression
A6: Adaptation | B6: LoRA / PEFT fine-tuning | C6: Kadekodi; Chen; Shukla; Agrawal | D6: AFX Sec. 4.1; Chen Sec. 5.1; Agrawal Sec. 3 | E6: LoRA rank 64: 85.1%; rank 16: 72.9% (Chen) | F6: Personalization / recovery
A7: Adaptation | B7: Decoupled adapters per subtask (tool selection vs arguments) | C7: Kadekodi | D7: Sec. 4.1 | E7: ToolFit 16.0% to 61.5% | F7: Personalization / recovery
A8: Adaptation | B8: Multi-LoRA weight merging | C8: Chen | D8: Sec. 5.2 | E8: 85.1% to 69.7% from 1 to 4 domains | F8: Personalization / recovery
A9: Adaptation | B9: Fine-tuning instead of long prompts to cut KV cache | C9: Chen | D9: Sec. 1; Sec. 3 | E9: Not measured on device | F9: Compression
A10: Architecture | B10: Planner and action model separation | C10: Chen | D10: Sec. 3.1 | E10: 98.1% in-domain | F10: Architecture
A11: Architecture | B11: Hierarchical toolset routing before tool selection | C11: Kadekodi | D11: Sec. 4.2 | E11: ToolFit 10.4% to 16.0% | F11: Fallback gate
A12: Architecture | B12: Agent topologies: single, hierarchical, peer-to-peer, hybrid | C12: Agrawal; Tian | D12: Agrawal Sec. 3; Tian Sec. 5.2 | E12: Qualitative | F12: Architecture
... A27: Evaluation | B27: Solution-, hardware- and co-design benchmarks for on-device learning | C27: Pavan | D27: Sec. 7 | E27: Proposed | F27: Evaluation

Sheet Frameworks
A1: Framework | B1: Taxonomy (deployment, role, topology, adaptation) | C1: Privacy | D1: Scalability | E1: Heterogeneity | F1: Autonomy | G1: Dimensions met (of 4)
A2: AgentsCoDriver | B2: On-device, domain control, peer-to-peer, static-prompt | C2: No | D2: No | E2: No | F2: Yes | G2: =COUNTIF(C2:F2,"Yes") -> 1
A3: MobileLLM | B3: On-device, user-facing, single, static-prompt | C3: Yes | D3: Yes | E3: Yes | F3: Yes | G3: =COUNTIF(C3:F3,"Yes") -> 4
A4: O-RAN | B4: Edge-hosted, system and operations, hierarchical, local fine-tuning | C4: No | D4: Yes | E4: No | F4: Yes | G4: =COUNTIF(C4:F4,"Yes") -> 2
A5: Industry 5.0 | B5: Edge-hosted, system and operations, hybrid multi-agent, static-prompt | C5: No | D5: Yes | E5: No | F5: Yes | G5: =COUNTIF(C5:F5,"Yes") -> 2
A6: Agentyxcrypt | B6: Edge-hosted, system and operations, peer-to-peer, static-prompt | C6: Yes | D6: No | E6: Yes | F6: No | G6: =COUNTIF(C6:F6,"Yes") -> 2
A8: Source: Agrawal, 'LLM-Based Agents on the Edge: A Survey ...', Table 1 (Sec. 5). The paper states no framework meets all four.

Sheet Recommendations
A1: ID | B1: Recommendation | C1: Method | D1: Metrics to report | E1: Supporting sources | F1: Status | G1: Notes / owner
A2: REC-1 | B2: Make fallback rate a measured, compression-dependent outcome | C2: Compress in levels (FP16, INT8, INT4, distilled/pruned); run each on a multi-step tool-use benchmark such as MCP-Bench | D2: Offline task-completion rate; fallback rate split by capability vs connectivity trigger; per-step failure compounding; IPW; peak RAM incl. KV cache and adapters; hardware-metered power | E2: Kadekodi Sec. 3.1; Saad-Falcon App. C, D.1; Ameur Sec. 6.2; Pavan Sec. 7 | F2: Not started
A3: REC-2 | B3: Add a step-level fallback gate with minimal-payload escalation | C3: Use tool-selection confidence as the gate; on escalation send only stripped or generalized context | D3: Bytes exposed per task; gate accuracy vs an ~80%-accurate router; cost per trajectory | E3: Al-Atat Sec. 4; Kadekodi Table 2; Agrawal Sec. 4.1; Saad-Falcon Sec. 4.3 | F3: Not started
A4: REC-3 | B4: Test personalization inside the same memory budget | C4: LoRA as recovery after compression and as personalization; measure forgetting and effect on fallback rate; run on real constrained hardware in a safety-critical domain | D4: Forgetting; fallback rate before/after adaptation; memory split (base, adapters, KV cache, buffer) | E4: Tian Sec. 7 item 1; Chen Table 2; Pavan Sec. 3, 7 | F4: Not started
A6: Core gap (from the analysis): no paper read measures how compression level affects completion of multi-step agentic tasks, what share of steps still need the cloud at each level, behavior under lost connectivity, or data sent at each fallback. Based only on these 12 papers; confirm with a wider search.
